[INFO|utils.py:32] 2021-07-20 16:17:56 Writing logs at ./logs/log-20210720-05.log
[INFO|main.py:32] 2021-07-20 16:17:56 **************************Load SemEval_Restaurants_2014 Dataset
[INFO|tokenization.py:190] 2021-07-20 16:17:57 loading vocabulary file https://s3.amazonaws.com/models.huggingface.co/bert/bert-base-uncased-vocab.txt from cache at /home/kkh/.pytorch_pretrained_bert/26bc1ad6c0ac742e9b52263248f6d0f00068293b33709fae12320c0e35ccfbbb.542ce4285a40d23a559526243235df47c5f75c197f04f37d1a0c124c32c9a084
[ERROR|main.py:149] 2021-07-20 16:17:57 ERROR
Traceback (most recent call last):
  File "main.py", line 147, in <module>
    main()
  File "main.py", line 140, in main
    trainLoader, testLoader, processor = load_dataset()
  File "main.py", line 39, in load_dataset
    train_feature = data_utils.convert_examples_to_features(train_examples, label_list, args.max_seq_length, tokenizer, "AE")
  File "/home/kkh/ABSA/data_utils.py", line 167, in convert_examples_to_features
    label_id = label_id
TypeError: __init__() got an unexpected keyword argument 'input_ids'
